2025-07-26 00:44:24,844 INFO    MainThread:36103 [wandb_setup.py:_flush():80] Current SDK version is 0.21.0
2025-07-26 00:44:24,844 INFO    MainThread:36103 [wandb_setup.py:_flush():80] Configure stats pid to 36103
2025-07-26 00:44:24,845 INFO    MainThread:36103 [wandb_setup.py:_flush():80] Loading settings from /Users/liubodong/.config/wandb/settings
2025-07-26 00:44:24,845 INFO    MainThread:36103 [wandb_setup.py:_flush():80] Loading settings from /Users/liubodong/Documents/dev/AI/U-Nets/notebooks/wandb/settings
2025-07-26 00:44:24,845 INFO    MainThread:36103 [wandb_setup.py:_flush():80] Loading settings from environment variables
2025-07-26 00:44:24,845 WARNING MainThread:36103 [wandb_setup.py:_flush():80] interrupted
Traceback (most recent call last):
  File "/opt/anaconda3/envs/nn/lib/python3.12/site-packages/IPython/core/interactiveshell.py", line 3672, in run_code
    exec(code_obj, self.user_global_ns, self.user_ns)
  File "/var/folders/d_/_f2s902j2wn_4mxfq3000rdc0000gn/T/ipykernel_36103/1578457327.py", line 6, in <module>
    run = wandb.init(
          ^^^^^^^^^^^
  File "/opt/anaconda3/envs/nn/lib/python3.12/site-packages/wandb/sdk/wandb_init.py", line 1548, in init
    wi.maybe_login(init_settings)
  File "/opt/anaconda3/envs/nn/lib/python3.12/site-packages/wandb/sdk/wandb_init.py", line 191, in maybe_login
    wandb_login._login(
  File "/opt/anaconda3/envs/nn/lib/python3.12/site-packages/wandb/sdk/wandb_login.py", line 326, in _login
    wlogin._print_logged_in_message()
  File "/opt/anaconda3/envs/nn/lib/python3.12/site-packages/wandb/sdk/wandb_login.py", line 136, in _print_logged_in_message
    username = self._wandb_setup._get_username()
               ^^^^^^^^^^^^^^^^^^^^^^^^^^^^^^^^^
  File "/opt/anaconda3/envs/nn/lib/python3.12/site-packages/wandb/sdk/wandb_setup.py", line 252, in _get_username
    return self.viewer.get("username")
           ^^^^^^^^^^^
  File "/opt/anaconda3/envs/nn/lib/python3.12/site-packages/wandb/sdk/wandb_setup.py", line 267, in viewer
    return self._server.viewer
           ^^^^^^^^^^^^^^^^^^^
  File "/opt/anaconda3/envs/nn/lib/python3.12/site-packages/wandb/sdk/lib/server.py", line 56, in viewer
    self.query_with_timeout()
  File "/opt/anaconda3/envs/nn/lib/python3.12/site-packages/wandb/sdk/lib/server.py", line 31, in query_with_timeout
    viewer_tuple, viewer_thread = async_viewer()
                                  ^^^^^^^^^^^^^^
  File "/opt/anaconda3/envs/nn/lib/python3.12/site-packages/wandb/util.py", line 1220, in wrapper
    result = q.get(True, timeout)
             ^^^^^^^^^^^^^^^^^^^^
  File "/opt/anaconda3/envs/nn/lib/python3.12/queue.py", line 180, in get
    self.not_empty.wait(remaining)
  File "/opt/anaconda3/envs/nn/lib/python3.12/threading.py", line 359, in wait
    gotit = waiter.acquire(True, timeout)
            ^^^^^^^^^^^^^^^^^^^^^^^^^^^^^
KeyboardInterrupt
2025-07-26 00:44:24,846 INFO    MainThread:36103 [wandb_init.py:setup_run_log_directory():703] Logging user logs to /Users/liubodong/Documents/dev/AI/U-Nets/notebooks/wandb/run-20250726_004424-quq2s8id/logs/debug.log
2025-07-26 00:44:24,846 INFO    MainThread:36103 [wandb_init.py:setup_run_log_directory():704] Logging internal logs to /Users/liubodong/Documents/dev/AI/U-Nets/notebooks/wandb/run-20250726_004424-quq2s8id/logs/debug-internal.log
2025-07-26 00:44:24,846 INFO    MainThread:36103 [wandb_init.py:monkeypatch_ipython():622] configuring jupyter hooks <wandb.sdk.wandb_init._WandbInit object at 0x126317650>
2025-07-26 00:44:24,846 INFO    MainThread:36103 [wandb_init.py:init():830] calling init triggers
2025-07-26 00:44:24,846 INFO    MainThread:36103 [wandb_init.py:init():835] wandb.init called with sweep_config: {}
config: {'learning_rate': 0.02, 'architecture': 'CNN', 'dataset': 'CIFAR-100', 'epochs': 10, '_wandb': {}}
2025-07-26 00:44:24,846 INFO    MainThread:36103 [wandb_init.py:init():871] starting backend
2025-07-26 00:44:25,475 INFO    MainThread:36103 [wandb_init.py:init():874] sending inform_init request
2025-07-26 00:44:25,489 INFO    MainThread:36103 [wandb_init.py:init():882] backend started and connected
2025-07-26 00:44:25,491 INFO    MainThread:36103 [wandb_run.py:_label_probe_notebook():1304] probe notebook
2025-07-26 00:44:25,492 INFO    MainThread:36103 [wandb_run.py:_label_probe_notebook():1314] Unable to probe notebook: Expecting value: line 1 column 1 (char 0)
2025-07-26 00:44:25,492 INFO    MainThread:36103 [wandb_init.py:init():953] updated telemetry
2025-07-26 00:44:25,513 INFO    MainThread:36103 [wandb_init.py:init():977] communicating run to backend with 90.0 second timeout
2025-07-26 00:44:39,847 INFO    Thread-6 (wrapped_target):36103 [retry.py:__call__():173] [no run ID] Retry attempt failed:
Traceback (most recent call last):
  File "/opt/anaconda3/envs/nn/lib/python3.12/site-packages/urllib3/connection.py", line 198, in _new_conn
    sock = connection.create_connection(
           ^^^^^^^^^^^^^^^^^^^^^^^^^^^^^
  File "/opt/anaconda3/envs/nn/lib/python3.12/site-packages/urllib3/util/connection.py", line 85, in create_connection
    raise err
  File "/opt/anaconda3/envs/nn/lib/python3.12/site-packages/urllib3/util/connection.py", line 73, in create_connection
    sock.connect(sa)
TimeoutError: timed out

The above exception was the direct cause of the following exception:

Traceback (most recent call last):
  File "/opt/anaconda3/envs/nn/lib/python3.12/site-packages/urllib3/connectionpool.py", line 787, in urlopen
    response = self._make_request(
               ^^^^^^^^^^^^^^^^^^^
  File "/opt/anaconda3/envs/nn/lib/python3.12/site-packages/urllib3/connectionpool.py", line 488, in _make_request
    raise new_e
  File "/opt/anaconda3/envs/nn/lib/python3.12/site-packages/urllib3/connectionpool.py", line 464, in _make_request
    self._validate_conn(conn)
  File "/opt/anaconda3/envs/nn/lib/python3.12/site-packages/urllib3/connectionpool.py", line 1093, in _validate_conn
    conn.connect()
  File "/opt/anaconda3/envs/nn/lib/python3.12/site-packages/urllib3/connection.py", line 753, in connect
    self.sock = sock = self._new_conn()
                       ^^^^^^^^^^^^^^^^
  File "/opt/anaconda3/envs/nn/lib/python3.12/site-packages/urllib3/connection.py", line 207, in _new_conn
    raise ConnectTimeoutError(
urllib3.exceptions.ConnectTimeoutError: (<urllib3.connection.HTTPSConnection object at 0x1263166f0>, 'Connection to api.wandb.ai timed out. (connect timeout=20)')

The above exception was the direct cause of the following exception:

Traceback (most recent call last):
  File "/opt/anaconda3/envs/nn/lib/python3.12/site-packages/requests/adapters.py", line 667, in send
    resp = conn.urlopen(
           ^^^^^^^^^^^^^
  File "/opt/anaconda3/envs/nn/lib/python3.12/site-packages/urllib3/connectionpool.py", line 841, in urlopen
    retries = retries.increment(
              ^^^^^^^^^^^^^^^^^^
  File "/opt/anaconda3/envs/nn/lib/python3.12/site-packages/urllib3/util/retry.py", line 519, in increment
    raise MaxRetryError(_pool, url, reason) from reason  # type: ignore[arg-type]
    ^^^^^^^^^^^^^^^^^^^^^^^^^^^^^^^^^^^^^^^^^^^^^^^^^^^
urllib3.exceptions.MaxRetryError: HTTPSConnectionPool(host='api.wandb.ai', port=443): Max retries exceeded with url: /graphql (Caused by ConnectTimeoutError(<urllib3.connection.HTTPSConnection object at 0x1263166f0>, 'Connection to api.wandb.ai timed out. (connect timeout=20)'))

During handling of the above exception, another exception occurred:

Traceback (most recent call last):
  File "/opt/anaconda3/envs/nn/lib/python3.12/site-packages/wandb/sdk/lib/retry.py", line 134, in __call__
    result = self._call_fn(*args, **kwargs)
             ^^^^^^^^^^^^^^^^^^^^^^^^^^^^^^
  File "/opt/anaconda3/envs/nn/lib/python3.12/site-packages/wandb/sdk/internal/internal_api.py", line 397, in execute
    return self.client.execute(*args, **kwargs)  # type: ignore
           ^^^^^^^^^^^^^^^^^^^^^^^^^^^^^^^^^^^^
  File "/opt/anaconda3/envs/nn/lib/python3.12/site-packages/wandb/vendor/gql-0.2.0/wandb_gql/client.py", line 52, in execute
    result = self._get_result(document, *args, **kwargs)
             ^^^^^^^^^^^^^^^^^^^^^^^^^^^^^^^^^^^^^^^^^^^
  File "/opt/anaconda3/envs/nn/lib/python3.12/site-packages/wandb/vendor/gql-0.2.0/wandb_gql/client.py", line 60, in _get_result
    return self.transport.execute(document, *args, **kwargs)
           ^^^^^^^^^^^^^^^^^^^^^^^^^^^^^^^^^^^^^^^^^^^^^^^^^
  File "/opt/anaconda3/envs/nn/lib/python3.12/site-packages/wandb/sdk/lib/gql_request.py", line 58, in execute
    request = self.session.post(self.url, **post_args)
              ^^^^^^^^^^^^^^^^^^^^^^^^^^^^^^^^^^^^^^^^
  File "/opt/anaconda3/envs/nn/lib/python3.12/site-packages/requests/sessions.py", line 637, in post
    return self.request("POST", url, data=data, json=json, **kwargs)
           ^^^^^^^^^^^^^^^^^^^^^^^^^^^^^^^^^^^^^^^^^^^^^^^^^^^^^^^^^
  File "/opt/anaconda3/envs/nn/lib/python3.12/site-packages/requests/sessions.py", line 589, in request
    resp = self.send(prep, **send_kwargs)
           ^^^^^^^^^^^^^^^^^^^^^^^^^^^^^^
  File "/opt/anaconda3/envs/nn/lib/python3.12/site-packages/requests/sessions.py", line 703, in send
    r = adapter.send(request, **kwargs)
        ^^^^^^^^^^^^^^^^^^^^^^^^^^^^^^^
  File "/opt/anaconda3/envs/nn/lib/python3.12/site-packages/requests/adapters.py", line 688, in send
    raise ConnectTimeout(e, request=request)
requests.exceptions.ConnectTimeout: HTTPSConnectionPool(host='api.wandb.ai', port=443): Max retries exceeded with url: /graphql (Caused by ConnectTimeoutError(<urllib3.connection.HTTPSConnection object at 0x1263166f0>, 'Connection to api.wandb.ai timed out. (connect timeout=20)'))
